<?xml version="1.0" ?>
<!-- =================================================================================== -->
<!-- |    This document was autogenerated by xacro from box.xacro                      | -->
<!-- |    EDITING THIS FILE BY HAND IS NOT RECOMMENDED                                 | -->
<!-- =================================================================================== -->
<robot name="rjje_arm">
  <!-- Instances -->
  <link name="world">
  </link>
  <link name="base_link">
    <inertial>
      <mass value="157.633"/>
      <origin rpy="0.0 0.0 0.0" xyz="0.0 0.0 0.0"/>
      <inertia ixx="13.235" ixy="0" ixz="0" iyy="13.235" iyz="0" izz="9.655"/>
    </inertial>
    <collision>
      <origin rpy="0.0 0.0 0.0" xyz="0.0 0.0 0.0"/>
      <geometry>
        <mesh filename="package://rjje_arm/meshes/cup_holder.stl" scale="0.1 0.1 0.1"/>
      </geometry>
    </collision>
    <visual>
      <origin rpy="0.0 0.0 0.0" xyz="0.0 0.0 0.0"/>
      <geometry>
        <mesh filename="package://rjje_arm/meshes/cup_holder.stl" scale="0.1 0.1 0.1"/>
      </geometry>
      <material name="light_black"/>
    </visual>
  </link>
  <joint name="$base_link_world" type="revolute">
    <axis xyz="0 0 1"/>
    <limit effort="1000" lower="0" upper="0.5" velocity="0.5"/>
    <origin rpy="0 0 0" xyz="0 0 0.0"/>
    <parent link="world"/>
    <child link="base_link"/>
  </joint>
</robot>

