<?xml version="1.0" ?>
<!-- =================================================================================== -->
<!-- |    This document was autogenerated by xacro from rjje_arm.xacro                 | -->
<!-- |    EDITING THIS FILE BY HAND IS NOT RECOMMENDED                                 | -->
<!-- =================================================================================== -->
<robot name="rjje_arm">
  <material name="blue">
    <color rgba="0 0 0.8 1"/>
  </material>
  <material name="yellow">
    <color rgba="0.93 0.93 0.02 1.0"/>
  </material>
  <material name="dark_green">
    <color rgba="0.2 0.2 0.1 1.0"/>
  </material>
  <!-- Instances -->
  <link name="world">
  </link>
  <link name="base_link">
    <inertial>
      <mass value="157.633"/>
      <origin rpy="0.0 0.0 0.0" xyz="0.0 0.0 0.0"/>
      <inertia ixx="13.235" ixy="0" ixz="0" iyy="13.235" iyz="0" izz="9.655"/>
    </inertial>
    <collision>
      <origin rpy="0.0 0.0 0.0" xyz="0.0 0.0 0.0"/>
      <geometry>
        <mesh filename="package://rjje_arm/meshes/base.stl" scale="1 1 1"/>
      </geometry>
    </collision>
    <visual>
      <origin rpy="0.0 0.0 0.0" xyz="0.0 0.0 0.0"/>
      <geometry>
        <mesh filename="package://rjje_arm/meshes/base.stl" scale="1 1 1"/>
      </geometry>
      <material name="yellow"/>
    </visual>
  </link>
  <joint name="world_base_link" type="fixed">
    <axis xyz="0 0 1"/>
    <limit effort="1000" lower="0" upper="0.5" velocity="0.5"/>
    <origin rpy="0 0 0" xyz="0 0 0.0"/>
    <parent link="world"/>
    <child link="base_link"/>
  </joint>
  <link name="link1">
    <inertial>
      <mass value="157.633"/>
      <origin rpy="0.0 0.0 0.0" xyz="0.0 0.0 0.0"/>
      <inertia ixx="13.235" ixy="0" ixz="0" iyy="13.235" iyz="0" izz="9.655"/>
    </inertial>
    <collision>
      <origin rpy="0.0 0.0 0.0" xyz="0.0 0.0 0.0"/>
      <geometry>
        <mesh filename="package://rjje_arm/meshes/motor_and_frame.stl" scale="1 1 1"/>
      </geometry>
    </collision>
    <visual>
      <origin rpy="0.0 0.0 0.0" xyz="0.0 0.0 0.0"/>
      <geometry>
        <mesh filename="package://rjje_arm/meshes/motor_and_frame.stl" scale="1 1 1"/>
      </geometry>
      <material name="dark_green"/>
    </visual>
  </link>
  <joint name="base_link_link1" type="fixed">
    <axis xyz="0 0 1"/>
    <limit effort="1000" lower="0" upper="0.5" velocity="0.5"/>
    <origin rpy="0 0 0" xyz="3.45 4.2 4.0"/>
    <parent link="base_link"/>
    <child link="link1"/>
  </joint>
  <link name="bracket_1">
    <inertial>
      <mass value="157.633"/>
      <origin rpy="0.0 0.0 3.14" xyz="0.0 0.0 0.0"/>
      <inertia ixx="13.235" ixy="0" ixz="0" iyy="13.235" iyz="0" izz="9.655"/>
    </inertial>
    <collision>
      <origin rpy="0.0 0.0 3.14" xyz="0.0 0.0 0.0"/>
      <geometry>
        <mesh filename="package://rjje_arm/meshes/thin_bracket.stl" scale="1 1 1"/>
      </geometry>
    </collision>
    <visual>
      <origin rpy="0.0 0.0 3.14" xyz="0.0 0.0 0.0"/>
      <geometry>
        <mesh filename="package://rjje_arm/meshes/thin_bracket.stl" scale="1 1 1"/>
      </geometry>
      <material name="blue"/>
    </visual>
  </link>
  <joint name="link1_bracket_1" type="revolute">
    <axis xyz="0 0 1"/>
    <limit effort="1000" lower="-1.57" upper="1.57" velocity="0.5"/>
    <origin rpy="0 0 0" xyz="0 0 5.3"/>
    <parent link="link1"/>
    <child link="bracket_1"/>
  </joint>
</robot>

