<?xml version="1.0" ?>
<!-- =================================================================================== -->
<!-- |    This document was autogenerated by xacro from rjje_arm.xacro                 | -->
<!-- |    EDITING THIS FILE BY HAND IS NOT RECOMMENDED                                 | -->
<!-- =================================================================================== -->
<robot name="rjje_arm">
  <material name="blue">
    <color rgba="0 0 0.8 1"/>
  </material>
  <material name="pink">
    <color rgba="1.0 0.71 0.76 1.0"/>
  </material>
  <material name="yellow">
    <color rgba="0.93 0.93 0.02 1.0"/>
  </material>
  <material name="dark_green">
    <color rgba="0.2 0.2 0.1 1.0"/>
  </material>
  <!-- Instances -->
  <link name="world">
  </link>
  <link name="base_link">
    <inertial>
      <mass value="157.633"/>
      <origin rpy="0.0 0.0 0.0" xyz="0.0 0.0 0.0"/>
      <inertia ixx="13.235" ixy="0" ixz="0" iyy="13.235" iyz="0" izz="9.655"/>
    </inertial>
    <collision>
      <origin rpy="0.0 0.0 0.0" xyz="0.0 0.0 0.0"/>
      <geometry>
        <mesh filename="package://rjje_arm/meshes/base.stl" scale="1 1 1"/>
      </geometry>
    </collision>
    <visual>
      <origin rpy="0.0 0.0 0.0" xyz="0.0 0.0 0.0"/>
      <geometry>
        <mesh filename="package://rjje_arm/meshes/base.stl" scale="1 1 1"/>
      </geometry>
      <material name="yellow"/>
    </visual>
  </link>
  <gazebo reference="base_link">
    <material>Gazebo/Yellow</material>
  </gazebo>
  <joint name="world_base_link" type="fixed">
    <axis xyz="0 0 1"/>
    <limit effort="1000" lower="0" upper="0.5" velocity="0.5"/>
    <origin rpy="0 0 0" xyz="0 0 0.0"/>
    <parent link="world"/>
    <child link="base_link"/>
  </joint>
  <link name="link1">
    <inertial>
      <mass value="157.633"/>
      <origin rpy="0.0 0.0 0.0" xyz="0.0 0.0 0.0"/>
      <inertia ixx="13.235" ixy="0" ixz="0" iyy="13.235" iyz="0" izz="9.655"/>
    </inertial>
    <collision>
      <origin rpy="0.0 0.0 0.0" xyz="0.0 0.0 0.0"/>
      <geometry>
        <mesh filename="package://rjje_arm/meshes/motor_and_frame.stl" scale="1 1 1"/>
      </geometry>
    </collision>
    <visual>
      <origin rpy="0.0 0.0 0.0" xyz="0.0 0.0 0.0"/>
      <geometry>
        <mesh filename="package://rjje_arm/meshes/motor_and_frame.stl" scale="1 1 1"/>
      </geometry>
      <material name="dark_green"/>
    </visual>
  </link>
  <joint name="base_link_link1" type="fixed">
    <axis xyz="0 0 1"/>
    <limit effort="1000" lower="0" upper="0.5" velocity="0.5"/>
    <origin rpy="0 0 0" xyz="3.45 4.2 4.0"/>
    <parent link="base_link"/>
    <child link="link1"/>
  </joint>
  <link name="bracket_1">
    <inertial>
      <mass value="157.633"/>
      <origin rpy="0.0 0.0 3.14" xyz="0.0 0.0 0.0"/>
      <inertia ixx="13.235" ixy="0" ixz="0" iyy="13.235" iyz="0" izz="9.655"/>
    </inertial>
    <collision>
      <origin rpy="0.0 0.0 3.14" xyz="0.0 0.0 0.0"/>
      <geometry>
        <mesh filename="package://rjje_arm/meshes/thin_bracket.stl" scale="1 1 1"/>
      </geometry>
    </collision>
    <visual>
      <origin rpy="0.0 0.0 3.14" xyz="0.0 0.0 0.0"/>
      <geometry>
        <mesh filename="package://rjje_arm/meshes/thin_bracket.stl" scale="1 1 1"/>
      </geometry>
      <material name="blue"/>
    </visual>
  </link>
  <joint name="link1_bracket_1" type="revolute">
    <axis xyz="0 0 1"/>
    <limit effort="1000" lower="-1.57" upper="1.57" velocity="1.5"/>
    <origin rpy="0 0 0" xyz="0 0 5.3"/>
    <parent link="link1"/>
    <child link="bracket_1"/>
  </joint>
  <link name="link_2">
    <inertial>
      <mass value="157.633"/>
      <origin rpy="0.0 0.0 0.0" xyz="0.0 0.0 0.0"/>
      <inertia ixx="13.235" ixy="0" ixz="0" iyy="13.235" iyz="0" izz="9.655"/>
    </inertial>
    <collision>
      <origin rpy="0.0 0.0 0.0" xyz="0.0 0.0 0.0"/>
      <geometry>
        <mesh filename="package://rjje_arm/meshes/motor_and_frame.stl" scale="1 1 1"/>
      </geometry>
    </collision>
    <visual>
      <origin rpy="0.0 0.0 0.0" xyz="0.0 0.0 0.0"/>
      <geometry>
        <mesh filename="package://rjje_arm/meshes/motor_and_frame.stl" scale="1 1 1"/>
      </geometry>
      <material name="dark_green"/>
    </visual>
  </link>
  <joint name="bracket_1_link_2" type="fixed">
    <axis xyz="0 0 1"/>
    <limit effort="1000" lower="-1.57" upper="1.57" velocity="0.5"/>
    <origin rpy="1.57 0.0 -1.57" xyz="2.2 0.0 1.4"/>
    <parent link="bracket_1"/>
    <child link="link_2"/>
  </joint>
  <link name="bracket_2_1">
    <inertial>
      <mass value="157.633"/>
      <origin rpy="0.0 0.0 0.0" xyz="0.0 0.0 0.0"/>
      <inertia ixx="13.235" ixy="0" ixz="0" iyy="13.235" iyz="0" izz="9.655"/>
    </inertial>
    <collision>
      <origin rpy="0.0 0.0 0.0" xyz="0.0 0.0 0.0"/>
      <geometry>
        <mesh filename="package://rjje_arm/meshes/thin_bracket.stl" scale="1 1 1"/>
      </geometry>
    </collision>
    <visual>
      <origin rpy="0.0 0.0 0.0" xyz="0.0 0.0 0.0"/>
      <geometry>
        <mesh filename="package://rjje_arm/meshes/thin_bracket.stl" scale="1 1 1"/>
      </geometry>
      <material name="blue"/>
    </visual>
  </link>
  <joint name="link_2_bracket_2_1" type="revolute">
    <axis xyz="0 0 1"/>
    <limit effort="1000" lower="-1.57" upper="1.57" velocity="1.5"/>
    <origin rpy="0.0 0.0 0.0" xyz="0.0 0.0 5.3"/>
    <parent link="link_2"/>
    <child link="bracket_2_1"/>
  </joint>
  <link name="bracket_2_2">
    <inertial>
      <mass value="157.633"/>
      <origin rpy="0.0 0.0 0.0" xyz="0.0 0.0 0.0"/>
      <inertia ixx="13.235" ixy="0" ixz="0" iyy="13.235" iyz="0" izz="9.655"/>
    </inertial>
    <collision>
      <origin rpy="0.0 0.0 0.0" xyz="0.0 0.0 0.0"/>
      <geometry>
        <mesh filename="package://rjje_arm/meshes/thin_bracket.stl" scale="1 1 1"/>
      </geometry>
    </collision>
    <visual>
      <origin rpy="0.0 0.0 0.0" xyz="0.0 0.0 0.0"/>
      <geometry>
        <mesh filename="package://rjje_arm/meshes/thin_bracket.stl" scale="1 1 1"/>
      </geometry>
      <material name="blue"/>
    </visual>
  </link>
  <joint name="bracket_2_1_bracket_2_2" type="fixed">
    <axis xyz="0 0 1"/>
    <limit effort="1000" lower="-1.57" upper="1.57" velocity="0.5"/>
    <origin rpy="0.0 0.0 3.14" xyz="0.0 10.5 0.0"/>
    <parent link="bracket_2_1"/>
    <child link="bracket_2_2"/>
  </joint>
  <link name="link_3">
    <inertial>
      <mass value="157.633"/>
      <origin rpy="0.0 0.0 0.0" xyz="0.0 0.0 0.0"/>
      <inertia ixx="13.235" ixy="0" ixz="0" iyy="13.235" iyz="0" izz="9.655"/>
    </inertial>
    <collision>
      <origin rpy="0.0 0.0 0.0" xyz="0.0 0.0 0.0"/>
      <geometry>
        <mesh filename="package://rjje_arm/meshes/motor_and_frame.stl" scale="1 1 1"/>
      </geometry>
    </collision>
    <visual>
      <origin rpy="0.0 0.0 0.0" xyz="0.0 0.0 0.0"/>
      <geometry>
        <mesh filename="package://rjje_arm/meshes/motor_and_frame.stl" scale="1 1 1"/>
      </geometry>
      <material name="dark_green"/>
    </visual>
  </link>
  <joint name="bracket_2_2_link_3" type="revolute">
    <axis xyz="0 0 1"/>
    <limit effort="1000" lower="-1.57" upper="1.57" velocity="1.5"/>
    <origin rpy="0.0 0.0 3.14" xyz="0.0 0.0 -5.3"/>
    <parent link="bracket_2_2"/>
    <child link="link_3"/>
  </joint>
  <link name="bracket_3_1">
    <visual>
      <origin rpy="0.0 0.0 0.0" xyz="0.0 0.0 0.75"/>
      <geometry>
        <cylinder length="1.5" radius="0.5"/>
      </geometry>
      <material name="pink"/>
    </visual>
    <collision>
      <origin rpy="0.0 0.0 0.0" xyz="0.0 0.0 0.75"/>
      <geometry>
        <cylinder length="1.5" radius="0.5"/>
      </geometry>
    </collision>
    <inertial>
      <mass value="0.1"/>
      <inertia ixx="0.03" ixy="0.0" ixz="0.0" iyy="0.03" iyz="0.0" izz="0.03"/>
    </inertial>
  </link>
  <joint name="link_3_bracket_3_1" type="fixed">
    <axis xyz="0 0 1"/>
    <limit effort="1000" lower="-1.57" upper="1.57" velocity="0.5"/>
    <origin rpy="0.0 1.57 0.0" xyz="4.0 0.0 2.0"/>
    <parent link="link_3"/>
    <child link="bracket_3_1"/>
  </joint>
  <link name="bracket_3_2">
    <inertial>
      <mass value="157.633"/>
      <origin rpy="0.0 0.0 0.0" xyz="0.0 0.0 0.0"/>
      <inertia ixx="13.235" ixy="0" ixz="0" iyy="13.235" iyz="0" izz="9.655"/>
    </inertial>
    <collision>
      <origin rpy="0.0 0.0 0.0" xyz="0.0 0.0 0.0"/>
      <geometry>
        <mesh filename="package://rjje_arm/meshes/thin_bracket.stl" scale="1 1 1"/>
      </geometry>
    </collision>
    <visual>
      <origin rpy="0.0 0.0 0.0" xyz="0.0 0.0 0.0"/>
      <geometry>
        <mesh filename="package://rjje_arm/meshes/thin_bracket.stl" scale="1 1 1"/>
      </geometry>
      <material name="blue"/>
    </visual>
  </link>
  <joint name="bracket_3_1_bracket_3_2" type="fixed">
    <axis xyz="0 0 1"/>
    <limit effort="1000" lower="-1.57" upper="1.57" velocity="0.5"/>
    <origin rpy="-1.57 0.0 1.57" xyz="-2.65 0.0 6.75"/>
    <parent link="bracket_3_1"/>
    <child link="bracket_3_2"/>
  </joint>
  <link name="link_4">
    <inertial>
      <mass value="157.633"/>
      <origin rpy="0.0 0.0 0.0" xyz="0.0 0.0 0.0"/>
      <inertia ixx="13.235" ixy="0" ixz="0" iyy="13.235" iyz="0" izz="9.655"/>
    </inertial>
    <collision>
      <origin rpy="0.0 0.0 0.0" xyz="0.0 0.0 0.0"/>
      <geometry>
        <mesh filename="package://rjje_arm/meshes/motor_and_frame.stl" scale="1 1 1"/>
      </geometry>
    </collision>
    <visual>
      <origin rpy="0.0 0.0 0.0" xyz="0.0 0.0 0.0"/>
      <geometry>
        <mesh filename="package://rjje_arm/meshes/motor_and_frame.stl" scale="1 1 1"/>
      </geometry>
      <material name="dark_green"/>
    </visual>
  </link>
  <joint name="bracket_3_2_link_4" type="revolute">
    <axis xyz="0 0 1"/>
    <limit effort="1000" lower="-1.57" upper="0.43" velocity="1.5"/>
    <origin rpy="0.0 0.0 -1.57" xyz="0.0 0.0 -5.3"/>
    <parent link="bracket_3_2"/>
    <child link="link_4"/>
  </joint>
  <link name="link_5">
    <inertial>
      <mass value="157.633"/>
      <origin rpy="0.0 0.0 0.0" xyz="0.0 0.0 0.0"/>
      <inertia ixx="13.235" ixy="0" ixz="0" iyy="13.235" iyz="0" izz="9.655"/>
    </inertial>
    <collision>
      <origin rpy="0.0 0.0 0.0" xyz="0.0 0.0 0.0"/>
      <geometry>
        <mesh filename="package://rjje_arm/meshes/motor_and_frame.stl" scale="1 1 1"/>
      </geometry>
    </collision>
    <visual>
      <origin rpy="0.0 0.0 0.0" xyz="0.0 0.0 0.0"/>
      <geometry>
        <mesh filename="package://rjje_arm/meshes/motor_and_frame.stl" scale="1 1 1"/>
      </geometry>
      <material name="dark_green"/>
    </visual>
  </link>
  <joint name="link_4_link_5" type="fixed">
    <axis xyz="0 0 1"/>
    <limit effort="1000" lower="-1.57" upper="1.57" velocity="0.5"/>
    <origin rpy="0.0 1.57 0.0" xyz="0.0 2.4 2.2"/>
    <parent link="link_4"/>
    <child link="link_5"/>
  </joint>
  <link name="link_6">
    <inertial>
      <mass value="157.633"/>
      <origin rpy="0.0 0.0 0.0" xyz="0.0 0.0 0.0"/>
      <inertia ixx="13.235" ixy="0" ixz="0" iyy="13.235" iyz="0" izz="9.655"/>
    </inertial>
    <collision>
      <origin rpy="0.0 0.0 0.0" xyz="0.0 0.0 0.0"/>
      <geometry>
        <mesh filename="package://rjje_arm/meshes/motor_and_frame.stl" scale="0 0 0"/>
      </geometry>
    </collision>
    <visual>
      <origin rpy="0.0 0.0 0.0" xyz="0.0 0.0 0.0"/>
      <geometry>
        <mesh filename="package://rjje_arm/meshes/motor_and_frame.stl" scale="0 0 0"/>
      </geometry>
      <material name="dark_green"/>
    </visual>
  </link>
  <joint name="link_5_link_6" type="revolute">
    <axis xyz="0 0 1"/>
    <limit effort="1000" lower="-1.57" upper="1.57" velocity="1.5"/>
    <origin rpy="0.0 0.0 0.0" xyz="0.0 0.0 0.0"/>
    <parent link="link_5"/>
    <child link="link_6"/>
  </joint>
  <link name="left_gripper">
    <inertial>
      <mass value="157.633"/>
      <origin rpy="0.0 0.0 0.0" xyz="0.0 0.0 0.0"/>
      <inertia ixx="13.235" ixy="0" ixz="0" iyy="13.235" iyz="0" izz="9.655"/>
    </inertial>
    <collision>
      <origin rpy="0.0 0.0 0.0" xyz="0.0 0.0 0.0"/>
      <geometry>
        <mesh filename="package://rjje_arm/meshes/left_gripper.stl" scale="1 1 1"/>
      </geometry>
    </collision>
    <visual>
      <origin rpy="0.0 0.0 0.0" xyz="0.0 0.0 0.0"/>
      <geometry>
        <mesh filename="package://rjje_arm/meshes/left_gripper.stl" scale="1 1 1"/>
      </geometry>
      <material name="yellow"/>
    </visual>
  </link>
  <joint name="link_6_left_gripper" type="revolute">
    <axis xyz="0 1 0"/>
    <limit effort="1000" lower="-0.61" upper="0.0" velocity="1.5"/>
    <origin rpy="0.0 0.0 0.0" xyz="0.0 0.0 5.2"/>
    <parent link="link_6"/>
    <child link="left_gripper"/>
  </joint>
  <link name="right_gripper">
    <inertial>
      <mass value="157.633"/>
      <origin rpy="0.0 0.0 0.0" xyz="0.0 0.0 0.0"/>
      <inertia ixx="13.235" ixy="0" ixz="0" iyy="13.235" iyz="0" izz="9.655"/>
    </inertial>
    <collision>
      <origin rpy="0.0 0.0 0.0" xyz="0.0 0.0 0.0"/>
      <geometry>
        <mesh filename="package://rjje_arm/meshes/right_gripper.stl" scale="1 1 1"/>
      </geometry>
    </collision>
    <visual>
      <origin rpy="0.0 0.0 0.0" xyz="0.0 0.0 0.0"/>
      <geometry>
        <mesh filename="package://rjje_arm/meshes/right_gripper.stl" scale="1 1 1"/>
      </geometry>
      <material name="yellow"/>
    </visual>
  </link>
  <joint name="link_6_right_gripper" type="revolute">
    <axis xyz="0 1 0"/>
    <limit effort="1000" lower="0.61" upper="0.0" velocity="1.5"/>
    <origin rpy="0.0 0.0 0.0" xyz="0.0 0.0 5.2"/>
    <parent link="link_6"/>
    <child link="right_gripper"/>
    <mimic joint="link_6_left_gripper" multiplier="-1" offset="0"/>
  </joint>
</robot>

